Workbook

Sheet Scenarios
A1: Scenario summary: Bull / Base / Bear | $ millions
A2: Bear/Bull = Base growth -/+ the deltas on the Assumptions sheet (Cloud +/-5pp, Search and YouTube +/-2pp). FY2026E = 2 actual quarters + 2 forecast quarters.
C4: FY2025A | D4: FY26E Bear | E4: FY26E Base | F4: FY26E Bull | G4: FY27E Bear | H4: FY27E Base | I4: FY27E Bull
A5: Google Cloud revenue | C5: =SUM(Model_Base!AA12:AD12) | D5: =SUM(Model_Bear!AE12:AH12) | E5: =SUM(Model_Base!AE12:AH12) | F5: =SUM(Model_Bull!AE12:AH12) | G5: =SUM(Model_Bear!AI12:AL12) | H5: =SUM(Model_Base!AI12:AL12) | I5: =SUM(Model_Bull!AI12:AL12)
A6: Search & other revenue | C6: =SUM(Model_Base!AA8:AD8) | D6: =SUM(Model_Bear!AE8:AH8) | E6: =SUM(Model_Base!AE8:AH8) | F6: =SUM(Model_Bull!AE8:AH8) | G6: =SUM(Model_Bear!AI8:AL8) | H6: =SUM(Model_Base!AI8:AL8) | I6: =SUM(Model_Bull!AI8:AL8)
A7: Total revenues | C7: =SUM(Model_Base!AA15:AD15) | D7: =SUM(Model_Bear!AE15:AH15) | E7: =SUM(Model_Base!AE15:AH15) | F7: =SUM(Model_Bull!AE15:AH15) | G7: =SUM(Model_Bear!AI15:AL15) | H7: =SUM(Model_Base!AI15:AL15) | I7: =SUM(Model_Bull!AI15:AL15)
A8: Gross profit | C8: =SUM(Model_Base!AA28:AD28) | D8: =SUM(Model_Bear!AE28:AH28) | E8: =SUM(Model_Base!AE28:AH28) | F8: =SUM(Model_Bull!AE28:AH28) | G8: =SUM(Model_Bear!AI28:AL28) | H8: =SUM(Model_Base!AI28:AL28) | I8: =SUM(Model_Bull!AI28:AL28)
A9: Operating expenses | C9: =SUM(Model_Base!AA34:AD34) | D9: =SUM(Model_Bear!AE34:AH34) | E9: =SUM(Model_Base!AE34:AH34) | F9: =SUM(Model_Bull!AE34:AH34) | G9: =SUM(Model_Bear!AI34:AL34) | H9: =SUM(Model_Base!AI34:AL34) | I9: =SUM(Model_Bull!AI34:AL34)
A10: Operating income | C10: =SUM(Model_Base!AA35:AD35) | D10: =SUM(Model_Bear!AE35:AH35) | E10: =SUM(Model_Base!AE35:AH35) | F10: =SUM(Model_Bull!AE35:AH35) | G10: =SUM(Model_Bear!AI35:AL35) | H10: =SUM(Model_Base!AI35:AL35) | I10: =SUM(Model_Bull!AI35:AL35)
A11: Operating margin | C11: =C10/C7 | D11: =D10/D7 | E11: =E10/E7 | F11: =F10/F7 | G11: =G10/G7 | H11: =H10/H7 | I11: =I10/I7
A12: Total revenue growth YoY | C12: =C7/SUM(Model_Base!W15:Z15)-1 | D12: =D7/$C$7-1 | E12: =E7/$C$7-1 | F12: =F7/$C$7-1 | G12: =G7/D7-1 | H12: =H7/E7-1 | I12: =I7/F7-1
A14: vs. Base case
A15: Operating income vs Base ($M) | D15: =D10-E10 | E15: =E10-E10 | F15: =F10-E10 | G15: =G10-H10 | H15: =H10-H10 | I15: =I10-H10
A16: Operating income vs Base (%) | D16: =D10/E10-1 | E16: =E10/E10-1 | F16: =F10/E10-1 | G16: =G10/H10-1 | H16: =H10/H10-1 | I16: =I10/H10-1
A17: Total revenue vs Base ($M) | D17: =D7-E7 | E17: =E7-E7 | F17: =F7-E7 | G17: =G7-H7 | H17: =H7-H7 | I17: =I7-H7

Sheet Assumptions
A1: Assumptions & scenario inputs
A2: Blue cells on blue fill are the only inputs. Everything else in the workbook is formula-driven.
A4: Growth fade factor (per quarter ahead) | C4: 0.9 | D4: Latest YoY growth is multiplied by fade^k for the k-th forecast quarter. 1.00 = carry growth forward unchanged. Backtest note: fading cost accuracy on Cloud (it kept accelerating) but is neutral elsewhere.
A7: Scenario deltas: percentage points added to each forecast quarter's YoY growth
A8: Segment | C8: Bear | D8: Base | E8: Bull
A9: Search & other | C9: -0.02 | D9: 0 | E9: 0.02
A10: YouTube ads | C10: -0.02 | D10: 0 | E10: 0.02
A11: Network | C11: 0 | D11: 0 | E11: 0
A12: Subscriptions, platforms & devices | C12: 0 | D12: 0 | E12: 0
A13: Google Cloud | C13: -0.05 | D13: 0 | E13: 0.05
A14: Other Bets | C14: 0 | D14: 0 | E14: 0
A17: Other fixed assumptions (documented, not inputs):
A18: - Cost of revenues, sales & marketing: % of revenue = trailing 4-quarter average ratio (rolling).
A19: - R&D and G&A: same method in Base; held at Base-case dollars in Bull/Bear (headcount/compute commitments don't flex with a revenue swing).
A20: - Hedging gains/losses and EC fines: forecast at zero.
A21: - Seasonality: each forecast quarter grows off the same quarter a year earlier, so the Q4 ad peak is carried automatically.

Sheet Model_Base
A1: Alphabet Inc. - quarterly P&L model (Base case) | $ millions
A2: Blue = hard-coded SEC history. Black = formula. Yellow-shaded columns = forecast. Source: SEC EDGAR XBRL (companyfacts + 10-Q/10-K instance documents).
A3: Quarter | C3: Q1'19 | D3: Q2'19 | E3: Q3'19 | F3: Q4'19 | G3: Q1'20 | H3: Q2'20 | I3: Q3'20 | J3: Q4'20 | K3: Q1'21 | L3: Q2'21 | M3: Q3'21 | N3: Q4'21 | O3: Q1'22 | P3: Q2'22 | Q3: Q3'22 | R3: Q4'22 | S3: Q1'23 | T3: Q2'23 | U3: Q3'23 | V3: Q4'23 | W3: Q1'24 | X3: Q2'24 | Y3: Q3'24 | Z3: Q4'24 | AA3: Q1'25 | AB3: Q2'25 | AC3: Q3'25 | AD3: Q4'25 | AE3: Q1'26 | AF3: Q2'26 | AG3: Q3'26 | AH3: Q4'26 | AI3: Q1'27 | AJ3: Q2'27 | AK3: Q3'27 | AL3: Q4'27
C4: 43555 | D4: 43646 | E4: 43738 | F4: 43830 | G4: 43921 | H4: 44012 | I4: 44104 | J4: 44196 | K4: 44286 | L4: 44377 | M4: 44469 | N4: 44561 | O4: 44651 | P4: 44742 | Q4: 44834 | R4: 44926 | S4: 45016 | T4: 45107 | U4: 45199 | V4: 45291 | W4: 45382 | X4: 45473 | Y4: 45565 | Z4: 45657 | AA4: 45747 | AB4: 45838 | AC4: 45930 | AD4: 46022 | AE4: 46112 | AF4: 46203 | AG4: 46295 | AH4: 46387 | AI4: 46477 | AJ4: 46568 | AK4: 46660 | AL4: 46752
C5: Actual | D5: Actual | E5: Actual | F5: Actual | G5: Actual | H5: Actual | I5: Actual | J5: Actual | K5: Actual | L5: Actual | M5: Actual | N5: Actual | O5: Actual | P5: Actual | Q5: Actual | R5: Actual | S5: Actual | T5: Actual | U5: Actual | V5: Actual | W5: Actual | X5: Actual | Y5: Actual | Z5: Actual | AA5: Actual | AB5: Actual | AC5: Actual | AD5: Actual | AE5: Actual | AF5: Actual | AG5: Forecast | AH5: Forecast | AI5: Forecast | AJ5: Forecast | AK5: Forecast | AL5: Forecast
A6: Quarters ahead (k) | AG6: 1 | AH6: 2 | AI6: 3 | AJ6: 4 | AK6: 5 | AL6: 6
A7: REVENUE
A8: Search & other | C8: 22547 | D8: 23642 | E8: 24741 | F8: 27185 | G8: 24502 | H8: 21319 | I8: 26338 | J8: 31903 | K8: 31879 | L8: 35845 | M8: 37926 | N8: 43301 | O8: 39618 | P8: 40689 | Q8: 39539 | R8: 42604 | S8: 40359 | T8: 42628 | U8: 44026 | V8: 48020 | W8: 46156 | X8: 48509 | Y8: 49385 | Z8: 54034 | AA8: 50702 | AB8: 54190 | AC8: 56567 | AD8: 63073 | AE8: 60399 | AF8: 63271 | AG8: =AC8*(1+AG45) | AH8: =AD8*(1+AH45) | AI8: =AE8*(1+AI45) | AJ8: =AF8*(1+AJ45) | AK8: =AG8*(1+AK45) | AL8: =AH8*(1+AL45)
A9: YouTube ads | C9: 3025 | D9: 3603 | E9: 3804 | F9: 4717 | G9: 4038 | H9: 3812 | I9: 5037 | J9: 6885 | K9: 6005 | L9: 7002 | M9: 7205 | N9: 8633 | O9: 6869 | P9: 7340 | Q9: 7071 | R9: 7963 | S9: 6693 | T9: 7665 | U9: 7952 | V9: 9200 | W9: 8090 | X9: 8663 | Y9: 8921 | Z9: 10473 | AA9: 8927 | AB9: 9796 | AC9: 10261 | AD9: 11383 | AE9: 9883 | AF9: 11055 | AG9: =AC9*(1+AG46) | AH9: =AD9*(1+AH46) | AI9: =AE9*(1+AI46) | AJ9: =AF9*(1+AJ46) | AK9: =AG9*(1+AK46) | AL9: =AH9*(1+AL46)
A10: Network | C10: 5015 | D10: 5249 | E10: 5251 | F10: 6032 | G10: 5223 | H10: 4736 | I10: 5720 | J10: 7411 | K10: 6800 | L10: 7597 | M10: 7999 | N10: 9305 | O10: 8174 | P10: 8259 | Q10: 7872 | R10: 8475 | S10: 7496 | T10: 7850 | U10: 7669 | V10: 8297 | W10: 7413 | X10: 7444 | Y10: 7548 | Z10: 7954 | AA10: 7256 | AB10: 7354 | AC10: 7354 | AD10: 7828 | AE10: 6971 | AF10: 7303 | AG10: =AC10*(1+AG47) | AH10: =AD10*(1+AH47) | AI10: =AE10*(1+AI47) | AJ10: =AF10*(1+AJ47) | AK10: =AG10*(1+AK47) | AL10: =AH10*(1+AL47)
A11: Subscriptions, platforms & devices | C11: 3620 | D11: 4080 | E11: 4050 | F11: 5264 | G11: 4435 | H11: 5124 | I11: 5478 | J11: 6674 | K11: 6494 | L11: 6623 | M11: 6754 | N11: 8161 | O11: 6811 | P11: 6553 | Q11: 6895 | R11: 8796 | S11: 7413 | T11: 8142 | U11: 8339 | V11: 10794 | W11: 8739 | X11: 9312 | Y11: 10656 | Z11: 11633 | AA11: 10379 | AB11: 11203 | AC11: 12870 | AD11: 13578 | AE11: 12384 | AF11: 12911 | AG11: =AC11*(1+AG48) | AH11: =AD11*(1+AH48) | AI11: =AE11*(1+AI48) | AJ11: =AF11*(1+AJ48) | AK11: =AG11*(1+AK48) | AL11: =AH11*(1+AL48)
A12: Google Cloud | C12: 1825 | D12: 2100 | E12: 2379 | F12: 2614 | G12: 2777 | H12: 3007 | I12: 3444 | J12: 3831 | K12: 4047 | L12: 4628 | M12: 4990 | N12: 5541 | O12: 5821 | P12: 6276 | Q12: 6868 | R12: 7315 | S12: 7454 | T12: 8031 | U12: 8411 | V12: 9192 | W12: 9574 | X12: 10347 | Y12: 11353 | Z12: 11955 | AA12: 12260 | AB12: 13624 | AC12: 15157 | AD12: 17664 | AE12: 20028 | AF12: 24768 | AG12: =AC12*(1+AG49) | AH12: =AD12*(1+AH49) | AI12: =AE12*(1+AI49) | AJ12: =AF12*(1+AJ49) | AK12: =AG12*(1+AK49) | AL12: =AH12*(1+AL49)
A13: Other Bets | C13: 170 | D13: 162 | E13: 155 | F13: 172 | G13: 135 | H13: 148 | I13: 178 | J13: 196 | K13: 198 | L13: 192 | M13: 182 | N13: 181 | O13: 440 | P13: 193 | Q13: 209 | R13: 226 | S13: 288 | T13: 285 | U13: 297 | V13: 657 | W13: 495 | X13: 365 | Y13: 388 | Z13: 400 | AA13: 450 | AB13: 373 | AC13: 344 | AD13: 370 | AE13: 411 | AF13: 382 | AG13: =AC13*(1+AG50) | AH13: =AD13*(1+AH50) | AI13: =AE13*(1+AI50) | AJ13: =AF13*(1+AJ50) | AK13: =AG13*(1+AK50) | AL13: =AH13*(1+AL50)
A14: Hedging gains / (losses) | C14: 137 | D14: 108 | E14: 119 | F14: 91 | G14: 49 | H14: 151 | I14: -22 | J14: -2 | K14: -109 | L14: -7 | M14: 62 | N14: 203 | O14: 278 | P14: 375 | Q14: 638 | R14: 669 | S14: 84 | T14: 3 | U14: -1 | V14: 150 | W14: 72 | X14: 102 | Y14: 17 | Z14: 20 | AA14: 260 | AB14: -112 | AC14: -207 | AD14: -68 | AE14: -180 | AF14: 106 | AG14: 0 | AH14: 0 | AI14: 0 | AJ14: 0 | AK14: 0 | AL14: 0
A15: Total revenues | C15: =SUM(C8:C14) | D15: =SUM(D8:D14) | E15: =SUM(E8:E14) | F15: =SUM(F8:F14) | G15: =SUM(G8:G14) | H15: =SUM(H8:H14) | I15: =SUM(I8:I14) | J15: =SUM(J8:J14) | ... AL15: =SUM(AL8:AL14)
A17: YoY GROWTH
A18: Search & other | G18: =G8/C8-1 | H18: =H8/D8-1 | I18: =I8/E8-1 | J18: =J8/F8-1 | K18: =K8/G8-1 | L18: =L8/H8-1 | M18: =M8/I8-1 | N18: =N8/J8-1 | ... AL18: =AL8/AH8-1
A19: YouTube ads | G19: =G9/C9-1 | H19: =H9/D9-1 | I19: =I9/E9-1 | J19: =J9/F9-1 | K19: =K9/G9-1 | L19: =L9/H9-1 | M19: =M9/I9-1 | N19: =N9/J9-1 | ... AL19: =AL9/AH9-1
A20: Network | G20: =G10/C10-1 | H20: =H10/D10-1 | I20: =I10/E10-1 | J20: =J10/F10-1 | K20: =K10/G10-1 | L20: =L10/H10-1 | M20: =M10/I10-1 | N20: =N10/J10-1 | ... AL20: =AL10/AH10-1
A21: Subscriptions, platforms & devices | G21: =G11/C11-1 | H21: =H11/D11-1 | I21: =I11/E11-1 | J21: =J11/F11-1 | K21: =K11/G11-1 | L21: =L11/H11-1 | M21: =M11/I11-1 | N21: =N11/J11-1 | ... AL21: =AL11/AH11-1
A22: Google Cloud | G22: =G12/C12-1 | H22: =H12/D12-1 | I22: =I12/E12-1 | J22: =J12/F12-1 | K22: =K12/G12-1 | L22: =L12/H12-1 | M22: =M12/I12-1 | N22: =N12/J12-1 | ... AL22: =AL12/AH12-1
A23: Other Bets | G23: =G13/C13-1 | H23: =H13/D13-1 | I23: =I13/E13-1 | J23: =J13/F13-1 | K23: =K13/G13-1 | L23: =L13/H13-1 | M23: =M13/I13-1 | N23: =N13/J13-1 | ... AL23: =AL13/AH13-1
A24: Total revenues | G24: =G15/C15-1 | H24: =H15/D15-1 | I24: =I15/E15-1 | J24: =J15/F15-1 | K24: =K15/G15-1 | L24: =L15/H15-1 | M24: =M15/I15-1 | N24: =N15/J15-1 | ... AL24: =AL15/AH15-1
A26: PROFIT & LOSS
A27: Cost of revenues | C27: 16012 | D27: 17296 | E27: 17568 | F27: 21020 | G27: 18982 | H27: 18553 | I27: 21117 | J27: 26080 | K27: 24103 | L27: 26227 | M27: 27621 | N27: 32988 | O27: 29599 | P27: 30104 | Q27: 31158 | R27: 35342 | S27: 30612 | T27: 31916 | U27: 33229 | V27: 37575 | W27: 33712 | X27: 35507 | Y27: 36474 | Z27: 40613 | AA27: 36361 | AB27: 39039 | AC27: 41369 | AD27: 45766 | AE27: 41271 | AF27: 45943 | AG27: =AG15*AG39 | AH27: =AH15*AH39 | AI27: =AI15*AI39 | AJ27: =AJ15*AJ39 | AK27: =AK15*AK39 | AL27: =AL15*AL39
A28: Gross profit | C28: =C15-C27 | D28: =D15-D27 | E28: =E15-E27 | F28: =F15-F27 | G28: =G15-G27 | H28: =H15-H27 | I28: =I15-I27 | J28: =J15-J27 | ... AL28: =AL15-AL27
A29: Gross margin | C29: =C28/C15 | D29: =D28/D15 | E29: =E28/E15 | F29: =F28/F15 | G29: =G28/G15 | H29: =H28/H15 | I29: =I28/I15 | J29: =J28/J15 | ... AL29: =AL28/AL15
A30: Research & development | C30: 6029 | D30: 6213 | E30: 6554 | F30: 7222 | G30: 6820 | H30: 6875 | I30: 6856 | J30: 7022 | K30: 7485 | L30: 7675 | M30: 7694 | N30: 8708 | O30: 9119 | P30: 9841 | Q30: 10273 | R30: 10267 | S30: 11468 | T30: 10588 | U30: 11258 | V30: 12113 | W30: 11903 | X30: 11860 | Y30: 12447 | Z30: 13116 | AA30: 13556 | AB30: 13808 | AC30: 15151 | AD30: 18572 | AE30: 17032 | AF30: 18219 | AG30: =AG15*AG40 | AH30: =AH15*AH40 | AI30: =AI15*AI40 | AJ30: =AJ15*AJ40 | AK30: =AK15*AK40 | AL30: =AL15*AL40
A31: Sales & marketing | C31: 3905 | D31: 4212 | E31: 4609 | F31: 5738 | G31: 4500 | H31: 3901 | I31: 4231 | J31: 5314 | K31: 4516 | L31: 5276 | M31: 5516 | N31: 7604 | O31: 5825 | P31: 6630 | Q31: 6929 | R31: 7183 | S31: 6533 | T31: 6781 | U31: 6884 | V31: 7719 | W31: 6426 | X31: 6792 | Y31: 7227 | Z31: 7363 | AA31: 6172 | AB31: 7101 | AC31: 7205 | AD31: 8215 | AE31: 7606 | AF31: 8403 | AG31: =AG15*AG41 | AH31: =AH15*AH41 | AI31: =AI15*AI41 | AJ31: =AJ15*AJ41 | AK31: =AK15*AK41 | AL31: =AL15*AL41
A32: General & administrative | C32: 2088 | D32: 2043 | E32: 2591 | F32: 2829 | G32: 2880 | H32: 2585 | I32: 2756 | J32: 2831 | K32: 2773 | L32: 3341 | M32: 3256 | N32: 4140 | O32: 3374 | P32: 3657 | Q32: 3597 | R32: 5096 | S32: 3759 | T32: 3481 | U32: 3979 | V32: 5206 | W32: 3026 | X32: 3158 | Y32: 3599 | Z32: 4405 | AA32: 3539 | AB32: 5209 | AC32: 7393 | AD32: 5341 | AE32: 4291 | AF32: 6461 | AG32: =AG15*AG42 | AH32: =AH15*AH42 | AI32: =AI15*AI42 | AJ32: =AJ15*AJ42 | AK32: =AK15*AK42 | AL32: =AL15*AL42
A33: European Commission fines | C33: 1697 | D33: 0 | E33: 0 | F33: 0 | G33: 0 | H33: 0 | I33: 0 | J33: 0 | K33: 0 | L33: 0 | M33: 0 | N33: 0 | O33: 0 | P33: 0 | Q33: 0 | R33: 0 | S33: 0 | T33: 0 | U33: 0 | V33: 0 | W33: 0 | X33: 0 | Y33: 0 | Z33: 0 | AA33: 0 | AB33: 0 | AC33: 0 | AD33: 0 | AE33: 0 | AF33: 0 | AG33: 0 | AH33: 0 | AI33: 0 | AJ33: 0 | AK33: 0 | AL33: 0
A34: Total operating expenses (R&D + S&M + G&A + fines) | C34: =C30+C31+C32+C33 | D34: =D30+D31+D32+D33 | E34: =E30+E31+E32+E33 | F34: =F30+F31+F32+F33 | G34: =G30+G31+G32+G33 | H34: =H30+H31+H32+H33 | I34: =I30+I31+I32+I33 | J34: =J30+J31+J32+J33 | ... AL34: =AL30+AL31+AL32+AL33
A35: Operating income | C35: =C28-C34 | D35: =D28-D34 | E35: =E28-E34 | F35: =F28-F34 | G35: =G28-G34 | H35: =H28-H34 | I35: =I28-I34 | J35: =J28-J34 | ... AL35: =AL28-AL34
A36: Operating margin | C36: =C35/C15 | D36: =D35/D15 | E36: =E35/E15 | F36: =F35/F15 | G36: =G35/G15 | H36: =H35/H15 | I36: =I35/I15 | J36: =J35/J15 | ... AL36: =AL35/AL15
A38: COST RATIOS (% of revenue; forecast = trailing 4-quarter average)
A39: Cost of revenues | C39: =C27/C15 | D39: =D27/D15 | E39: =E27/E15 | F39: =F27/F15 | G39: =G27/G15 | H39: =H27/H15 | I39: =I27/I15 | J39: =J27/J15 | ... AF39: =AF27/AF15 | AG39: =AVERAGE(AC39:AF39) | AH39: =AVERAGE(AD39:AG39) | AI39: =AVERAGE(AE39:AH39) | AJ39: =AVERAGE(AF39:AI39) | AK39: =AVERAGE(AG39:AJ39) | AL39: =AVERAGE(AH39:AK39)
A40: R&D | C40: =C30/C15 | D40: =D30/D15 | E40: =E30/E15 | F40: =F30/F15 | G40: =G30/G15 | H40: =H30/H15 | I40: =I30/I15 | J40: =J30/J15 | ... AF40: =AF30/AF15 | AG40: =AVERAGE(AC40:AF40) | AH40: =AVERAGE(AD40:AG40) | AI40: =AVERAGE(AE40:AH40) | AJ40: =AVERAGE(AF40:AI40) | AK40: =AVERAGE(AG40:AJ40) | AL40: =AVERAGE(AH40:AK40)
A41: Sales & marketing | C41: =C31/C15 | D41: =D31/D15 | E41: =E31/E15 | F41: =F31/F15 | G41: =G31/G15 | H41: =H31/H15 | I41: =I31/I15 | J41: =J31/J15 | ... AF41: =AF31/AF15 | AG41: =AVERAGE(AC41:AF41) | AH41: =AVERAGE(AD41:AG41) | AI41: =AVERAGE(AE41:AH41) | AJ41: =AVERAGE(AF41:AI41) | AK41: =AVERAGE(AG41:AJ41) | AL41: =AVERAGE(AH41:AK41)
A42: G&A | C42: =C32/C15 | D42: =D32/D15 | E42: =E32/E15 | F42: =F32/F15 | G42: =G32/G15 | H42: =H32/H15 | I42: =I32/I15 | J42: =J32/J15 | ... AF42: =AF32/AF15 | AG42: =AVERAGE(AC42:AF42) | AH42: =AVERAGE(AD42:AG42) | AI42: =AVERAGE(AE42:AH42) | AJ42: =AVERAGE(AF42:AI42) | AK42: =AVERAGE(AG42:AJ42) | AL42: =AVERAGE(AH42:AK42)
A44: GROWTH ASSUMPTIONS = latest actual YoY x fade^k + scenario delta
...

Sheet Model_Bull
A1: Alphabet Inc. - quarterly P&L model (Bull case) | $ millions
A2: Blue = hard-coded SEC history. Black = formula. Yellow-shaded columns = forecast. Source: SEC EDGAR XBRL (companyfacts + 10-Q/10-K instance documents).
A3: Quarter | C3: Q1'19 | D3: Q2'19 | E3: Q3'19 | F3: Q4'19 | G3: Q1'20 | H3: Q2'20 | I3: Q3'20 | J3: Q4'20 | K3: Q1'21 | L3: Q2'21 | M3: Q3'21 | N3: Q4'21 | O3: Q1'22 | P3: Q2'22 | Q3: Q3'22 | R3: Q4'22 | S3: Q1'23 | T3: Q2'23 | U3: Q3'23 | V3: Q4'23 | W3: Q1'24 | X3: Q2'24 | Y3: Q3'24 | Z3: Q4'24 | AA3: Q1'25 | AB3: Q2'25 | AC3: Q3'25 | AD3: Q4'25 | AE3: Q1'26 | AF3: Q2'26 | AG3: Q3'26 | AH3: Q4'26 | AI3: Q1'27 | AJ3: Q2'27 | AK3: Q3'27 | AL3: Q4'27
C4: 43555 | D4: 43646 | E4: 43738 | F4: 43830 | G4: 43921 | H4: 44012 | I4: 44104 | J4: 44196 | K4: 44286 | L4: 44377 | M4: 44469 | N4: 44561 | O4: 44651 | P4: 44742 | Q4: 44834 | R4: 44926 | S4: 45016 | T4: 45107 | U4: 45199 | V4: 45291 | W4: 45382 | X4: 45473 | Y4: 45565 | Z4: 45657 | AA4: 45747 | AB4: 45838 | AC4: 45930 | AD4: 46022 | AE4: 46112 | AF4: 46203 | AG4: 46295 | AH4: 46387 | AI4: 46477 | AJ4: 46568 | AK4: 46660 | AL4: 46752
C5: Actual | D5: Actual | E5: Actual | F5: Actual | G5: Actual | H5: Actual | I5: Actual | J5: Actual | K5: Actual | L5: Actual | M5: Actual | N5: Actual | O5: Actual | P5: Actual | Q5: Actual | R5: Actual | S5: Actual | T5: Actual | U5: Actual | V5: Actual | W5: Actual | X5: Actual | Y5: Actual | Z5: Actual | AA5: Actual | AB5: Actual | AC5: Actual | AD5: Actual | AE5: Actual | AF5: Actual | AG5: Forecast | AH5: Forecast | AI5: Forecast | AJ5: Forecast | AK5: Forecast | AL5: Forecast
A6: Quarters ahead (k) | AG6: 1 | AH6: 2 | AI6: 3 | AJ6: 4 | AK6: 5 | AL6: 6
A7: REVENUE
A8: Search & other | C8: =Model_Base!C8 | D8: =Model_Base!D8 | E8: =Model_Base!E8 | F8: =Model_Base!F8 | G8: =Model_Base!G8 | H8: =Model_Base!H8 | I8: =Model_Base!I8 | J8: =Model_Base!J8 | ... AF8: =Model_Base!AF8 | AG8: =AC8*(1+AG45) | AH8: =AD8*(1+AH45) | AI8: =AE8*(1+AI45) | AJ8: =AF8*(1+AJ45) | AK8: =AG8*(1+AK45) | AL8: =AH8*(1+AL45)
A9: YouTube ads | C9: =Model_Base!C9 | D9: =Model_Base!D9 | E9: =Model_Base!E9 | F9: =Model_Base!F9 | G9: =Model_Base!G9 | H9: =Model_Base!H9 | I9: =Model_Base!I9 | J9: =Model_Base!J9 | ... AF9: =Model_Base!AF9 | AG9: =AC9*(1+AG46) | AH9: =AD9*(1+AH46) | AI9: =AE9*(1+AI46) | AJ9: =AF9*(1+AJ46) | AK9: =AG9*(1+AK46) | AL9: =AH9*(1+AL46)
A10: Network | C10: =Model_Base!C10 | D10: =Model_Base!D10 | E10: =Model_Base!E10 | F10: =Model_Base!F10 | G10: =Model_Base!G10 | H10: =Model_Base!H10 | I10: =Model_Base!I10 | J10: =Model_Base!J10 | ... AF10: =Model_Base!AF10 | AG10: =AC10*(1+AG47) | AH10: =AD10*(1+AH47) | AI10: =AE10*(1+AI47) | AJ10: =AF10*(1+AJ47) | AK10: =AG10*(1+AK47) | AL10: =AH10*(1+AL47)
A11: Subscriptions, platforms & devices | C11: =Model_Base!C11 | D11: =Model_Base!D11 | E11: =Model_Base!E11 | F11: =Model_Base!F11 | G11: =Model_Base!G11 | H11: =Model_Base!H11 | I11: =Model_Base!I11 | J11: =Model_Base!J11 | ... AF11: =Model_Base!AF11 | AG11: =AC11*(1+AG48) | AH11: =AD11*(1+AH48) | AI11: =AE11*(1+AI48) | AJ11: =AF11*(1+AJ48) | AK11: =AG11*(1+AK48) | AL11: =AH11*(1+AL48)
A12: Google Cloud | C12: =Model_Base!C12 | D12: =Model_Base!D12 | E12: =Model_Base!E12 | F12: =Model_Base!F12 | G12: =Model_Base!G12 | H12: =Model_Base!H12 | I12: =Model_Base!I12 | J12: =Model_Base!J12 | ... AF12: =Model_Base!AF12 | AG12: =AC12*(1+AG49) | AH12: =AD12*(1+AH49) | AI12: =AE12*(1+AI49) | AJ12: =AF12*(1+AJ49) | AK12: =AG12*(1+AK49) | AL12: =AH12*(1+AL49)
A13: Other Bets | C13: =Model_Base!C13 | D13: =Model_Base!D13 | E13: =Model_Base!E13 | F13: =Model_Base!F13 | G13: =Model_Base!G13 | H13: =Model_Base!H13 | I13: =Model_Base!I13 | J13: =Model_Base!J13 | ... AF13: =Model_Base!AF13 | AG13: =AC13*(1+AG50) | AH13: =AD13*(1+AH50) | AI13: =AE13*(1+AI50) | AJ13: =AF13*(1+AJ50) | AK13: =AG13*(1+AK50) | AL13: =AH13*(1+AL50)
A14: Hedging gains / (losses) | C14: =Model_Base!C14 | D14: =Model_Base!D14 | E14: =Model_Base!E14 | F14: =Model_Base!F14 | G14: =Model_Base!G14 | H14: =Model_Base!H14 | I14: =Model_Base!I14 | J14: =Model_Base!J14 | ... AF14: =Model_Base!AF14 | AG14: 0 | AH14: 0 | AI14: 0 | AJ14: 0 | AK14: 0 | AL14: 0
A15: Total revenues | C15: =SUM(C8:C14) | D15: =SUM(D8:D14) | E15: =SUM(E8:E14) | F15: =SUM(F8:F14) | G15: =SUM(G8:G14) | H15: =SUM(H8:H14) | I15: =SUM(I8:I14) | J15: =SUM(J8:J14) | ... AL15: =SUM(AL8:AL14)
A17: YoY GROWTH
A18: Search & other | G18: =G8/C8-1 | H18: =H8/D8-1 | I18: =I8/E8-1 | J18: =J8/F8-1 | K18: =K8/G8-1 | L18: =L8/H8-1 | M18: =M8/I8-1 | N18: =N8/J8-1 | ... AL18: =AL8/AH8-1
A19: YouTube ads | G19: =G9/C9-1 | H19: =H9/D9-1 | I19: =I9/E9-1 | J19: =J9/F9-1 | K19: =K9/G9-1 | L19: =L9/H9-1 | M19: =M9/I9-1 | N19: =N9/J9-1 | ... AL19: =AL9/AH9-1
A20: Network | G20: =G10/C10-1 | H20: =H10/D10-1 | I20: =I10/E10-1 | J20: =J10/F10-1 | K20: =K10/G10-1 | L20: =L10/H10-1 | M20: =M10/I10-1 | N20: =N10/J10-1 | ... AL20: =AL10/AH10-1
A21: Subscriptions, platforms & devices | G21: =G11/C11-1 | H21: =H11/D11-1 | I21: =I11/E11-1 | J21: =J11/F11-1 | K21: =K11/G11-1 | L21: =L11/H11-1 | M21: =M11/I11-1 | N21: =N11/J11-1 | ... AL21: =AL11/AH11-1
A22: Google Cloud | G22: =G12/C12-1 | H22: =H12/D12-1 | I22: =I12/E12-1 | J22: =J12/F12-1 | K22: =K12/G12-1 | L22: =L12/H12-1 | M22: =M12/I12-1 | N22: =N12/J12-1 | ... AL22: =AL12/AH12-1
A23: Other Bets | G23: =G13/C13-1 | H23: =H13/D13-1 | I23: =I13/E13-1 | J23: =J13/F13-1 | K23: =K13/G13-1 | L23: =L13/H13-1 | M23: =M13/I13-1 | N23: =N13/J13-1 | ... AL23: =AL13/AH13-1
A24: Total revenues | G24: =G15/C15-1 | H24: =H15/D15-1 | I24: =I15/E15-1 | J24: =J15/F15-1 | K24: =K15/G15-1 | L24: =L15/H15-1 | M24: =M15/I15-1 | N24: =N15/J15-1 | ... AL24: =AL15/AH15-1
A26: PROFIT & LOSS
A27: Cost of revenues | C27: =Model_Base!C27 | D27: =Model_Base!D27 | E27: =Model_Base!E27 | F27: =Model_Base!F27 | G27: =Model_Base!G27 | H27: =Model_Base!H27 | I27: =Model_Base!I27 | J27: =Model_Base!J27 | ... AF27: =Model_Base!AF27 | AG27: =AG15*AG39 | AH27: =AH15*AH39 | AI27: =AI15*AI39 | AJ27: =AJ15*AJ39 | AK27: =AK15*AK39 | AL27: =AL15*AL39
A28: Gross profit | C28: =C15-C27 | D28: =D15-D27 | E28: =E15-E27 | F28: =F15-F27 | G28: =G15-G27 | H28: =H15-H27 | I28: =I15-I27 | J28: =J15-J27 | ... AL28: =AL15-AL27
A29: Gross margin | C29: =C28/C15 | D29: =D28/D15 | E29: =E28/E15 | F29: =F28/F15 | G29: =G28/G15 | H29: =H28/H15 | I29: =I28/I15 | J29: =J28/J15 | ... AL29: =AL28/AL15
A30: Research & development | C30: =Model_Base!C30 | D30: =Model_Base!D30 | E30: =Model_Base!E30 | F30: =Model_Base!F30 | G30: =Model_Base!G30 | H30: =Model_Base!H30 | I30: =Model_Base!I30 | J30: =Model_Base!J30 | ... AL30: =Model_Base!AL30
A31: Sales & marketing | C31: =Model_Base!C31 | D31: =Model_Base!D31 | E31: =Model_Base!E31 | F31: =Model_Base!F31 | G31: =Model_Base!G31 | H31: =Model_Base!H31 | I31: =Model_Base!I31 | J31: =Model_Base!J31 | ... AF31: =Model_Base!AF31 | AG31: =AG15*AG41 | AH31: =AH15*AH41 | AI31: =AI15*AI41 | AJ31: =AJ15*AJ41 | AK31: =AK15*AK41 | AL31: =AL15*AL41
A32: General & administrative | C32: =Model_Base!C32 | D32: =Model_Base!D32 | E32: =Model_Base!E32 | F32: =Model_Base!F32 | G32: =Model_Base!G32 | H32: =Model_Base!H32 | I32: =Model_Base!I32 | J32: =Model_Base!J32 | ... AL32: =Model_Base!AL32
A33: European Commission fines | C33: =Model_Base!C33 | D33: =Model_Base!D33 | E33: =Model_Base!E33 | F33: =Model_Base!F33 | G33: =Model_Base!G33 | H33: =Model_Base!H33 | I33: =Model_Base!I33 | J33: =Model_Base!J33 | ... AF33: =Model_Base!AF33 | AG33: 0 | AH33: 0 | AI33: 0 | AJ33: 0 | AK33: 0 | AL33: 0
A34: Total operating expenses (R&D + S&M + G&A + fines) | C34: =C30+C31+C32+C33 | D34: =D30+D31+D32+D33 | E34: =E30+E31+E32+E33 | F34: =F30+F31+F32+F33 | G34: =G30+G31+G32+G33 | H34: =H30+H31+H32+H33 | I34: =I30+I31+I32+I33 | J34: =J30+J31+J32+J33 | ... AL34: =AL30+AL31+AL32+AL33
A35: Operating income | C35: =C28-C34 | D35: =D28-D34 | E35: =E28-E34 | F35: =F28-F34 | G35: =G28-G34 | H35: =H28-H34 | I35: =I28-I34 | J35: =J28-J34 | ... AL35: =AL28-AL34
A36: Operating margin | C36: =C35/C15 | D36: =D35/D15 | E36: =E35/E15 | F36: =F35/F15 | G36: =G35/G15 | H36: =H35/H15 | I36: =I35/I15 | J36: =J35/J15 | ... AL36: =AL35/AL15
A38: COST RATIOS (% of revenue; forecast = trailing 4-quarter average)
A39: Cost of revenues | C39: =C27/C15 | D39: =D27/D15 | E39: =E27/E15 | F39: =F27/F15 | G39: =G27/G15 | H39: =H27/H15 | I39: =I27/I15 | J39: =J27/J15 | ... AF39: =AF27/AF15 | AG39: =AVERAGE(AC39:AF39) | AH39: =AVERAGE(AD39:AG39) | AI39: =AVERAGE(AE39:AH39) | AJ39: =AVERAGE(AF39:AI39) | AK39: =AVERAGE(AG39:AJ39) | AL39: =AVERAGE(AH39:AK39)
A40: R&D | C40: =C30/C15 | D40: =D30/D15 | E40: =E30/E15 | F40: =F30/F15 | G40: =G30/G15 | H40: =H30/H15 | I40: =I30/I15 | J40: =J30/J15 | ... AF40: =AF30/AF15 | AG40: =AVERAGE(AC40:AF40) | AH40: =AVERAGE(AD40:AG40) | AI40: =AVERAGE(AE40:AH40) | AJ40: =AVERAGE(AF40:AI40) | AK40: =AVERAGE(AG40:AJ40) | AL40: =AVERAGE(AH40:AK40)
A41: Sales & marketing | C41: =C31/C15 | D41: =D31/D15 | E41: =E31/E15 | F41: =F31/F15 | G41: =G31/G15 | H41: =H31/H15 | I41: =I31/I15 | J41: =J31/J15 | ... AF41: =AF31/AF15 | AG41: =AVERAGE(AC41:AF41) | AH41: =AVERAGE(AD41:AG41) | AI41: =AVERAGE(AE41:AH41) | AJ41: =AVERAGE(AF41:AI41) | AK41: =AVERAGE(AG41:AJ41) | AL41: =AVERAGE(AH41:AK41)
A42: G&A | C42: =C32/C15 | D42: =D32/D15 | E42: =E32/E15 | F42: =F32/F15 | G42: =G32/G15 | H42: =H32/H15 | I42: =I32/I15 | J42: =J32/J15 | ... AF42: =AF32/AF15 | AG42: =AVERAGE(AC42:AF42) | AH42: =AVERAGE(AD42:AG42) | AI42: =AVERAGE(AE42:AH42) | AJ42: =AVERAGE(AF42:AI42) | AK42: =AVERAGE(AG42:AJ42) | AL42: =AVERAGE(AH42:AK42)
A44: GROWTH ASSUMPTIONS = latest actual YoY x fade^k + scenario delta
...

Sheet Model_Bear
A1: Alphabet Inc. - quarterly P&L model (Bear case) | $ millions
A2: Blue = hard-coded SEC history. Black = formula. Yellow-shaded columns = forecast. Source: SEC EDGAR XBRL (companyfacts + 10-Q/10-K instance documents).
A3: Quarter | C3: Q1'19 | D3: Q2'19 | E3: Q3'19 | F3: Q4'19 | G3: Q1'20 | H3: Q2'20 | I3: Q3'20 | J3: Q4'20 | K3: Q1'21 | L3: Q2'21 | M3: Q3'21 | N3: Q4'21 | O3: Q1'22 | P3: Q2'22 | Q3: Q3'22 | R3: Q4'22 | S3: Q1'23 | T3: Q2'23 | U3: Q3'23 | V3: Q4'23 | W3: Q1'24 | X3: Q2'24 | Y3: Q3'24 | Z3: Q4'24 | AA3: Q1'25 | AB3: Q2'25 | AC3: Q3'25 | AD3: Q4'25 | AE3: Q1'26 | AF3: Q2'26 | AG3: Q3'26 | AH3: Q4'26 | AI3: Q1'27 | AJ3: Q2'27 | AK3: Q3'27 | AL3: Q4'27
C4: 43555 | D4: 43646 | E4: 43738 | F4: 43830 | G4: 43921 | H4: 44012 | I4: 44104 | J4: 44196 | K4: 44286 | L4: 44377 | M4: 44469 | N4: 44561 | O4: 44651 | P4: 44742 | Q4: 44834 | R4: 44926 | S4: 45016 | T4: 45107 | U4: 45199 | V4: 45291 | W4: 45382 | X4: 45473 | Y4: 45565 | Z4: 45657 | AA4: 45747 | AB4: 45838 | AC4: 45930 | AD4: 46022 | AE4: 46112 | AF4: 46203 | AG4: 46295 | AH4: 46387 | AI4: 46477 | AJ4: 46568 | AK4: 46660 | AL4: 46752
C5: Actual | D5: Actual | E5: Actual | F5: Actual | G5: Actual | H5: Actual | I5: Actual | J5: Actual | K5: Actual | L5: Actual | M5: Actual | N5: Actual | O5: Actual | P5: Actual | Q5: Actual | R5: Actual | S5: Actual | T5: Actual | U5: Actual | V5: Actual | W5: Actual | X5: Actual | Y5: Actual | Z5: Actual | AA5: Actual | AB5: Actual | AC5: Actual | AD5: Actual | AE5: Actual | AF5: Actual | AG5: Forecast | AH5: Forecast | AI5: Forecast | AJ5: Forecast | AK5: Forecast | AL5: Forecast
A6: Quarters ahead (k) | AG6: 1 | AH6: 2 | AI6: 3 | AJ6: 4 | AK6: 5 | AL6: 6
A7: REVENUE
A8: Search & other | C8: =Model_Base!C8 | D8: =Model_Base!D8 | E8: =Model_Base!E8 | F8: =Model_Base!F8 | G8: =Model_Base!G8 | H8: =Model_Base!H8 | I8: =Model_Base!I8 | J8: =Model_Base!J8 | ... AF8: =Model_Base!AF8 | AG8: =AC8*(1+AG45) | AH8: =AD8*(1+AH45) | AI8: =AE8*(1+AI45) | AJ8: =AF8*(1+AJ45) | AK8: =AG8*(1+AK45) | AL8: =AH8*(1+AL45)
A9: YouTube ads | C9: =Model_Base!C9 | D9: =Model_Base!D9 | E9: =Model_Base!E9 | F9: =Model_Base!F9 | G9: =Model_Base!G9 | H9: =Model_Base!H9 | I9: =Model_Base!I9 | J9: =Model_Base!J9 | ... AF9: =Model_Base!AF9 | AG9: =AC9*(1+AG46) | AH9: =AD9*(1+AH46) | AI9: =AE9*(1+AI46) | AJ9: =AF9*(1+AJ46) | AK9: =AG9*(1+AK46) | AL9: =AH9*(1+AL46)
A10: Network | C10: =Model_Base!C10 | D10: =Model_Base!D10 | E10: =Model_Base!E10 | F10: =Model_Base!F10 | G10: =Model_Base!G10 | H10: =Model_Base!H10 | I10: =Model_Base!I10 | J10: =Model_Base!J10 | ... AF10: =Model_Base!AF10 | AG10: =AC10*(1+AG47) | AH10: =AD10*(1+AH47) | AI10: =AE10*(1+AI47) | AJ10: =AF10*(1+AJ47) | AK10: =AG10*(1+AK47) | AL10: =AH10*(1+AL47)
A11: Subscriptions, platforms & devices | C11: =Model_Base!C11 | D11: =Model_Base!D11 | E11: =Model_Base!E11 | F11: =Model_Base!F11 | G11: =Model_Base!G11 | H11: =Model_Base!H11 | I11: =Model_Base!I11 | J11: =Model_Base!J11 | ... AF11: =Model_Base!AF11 | AG11: =AC11*(1+AG48) | AH11: =AD11*(1+AH48) | AI11: =AE11*(1+AI48) | AJ11: =AF11*(1+AJ48) | AK11: =AG11*(1+AK48) | AL11: =AH11*(1+AL48)
A12: Google Cloud | C12: =Model_Base!C12 | D12: =Model_Base!D12 | E12: =Model_Base!E12 | F12: =Model_Base!F12 | G12: =Model_Base!G12 | H12: =Model_Base!H12 | I12: =Model_Base!I12 | J12: =Model_Base!J12 | ... AF12: =Model_Base!AF12 | AG12: =AC12*(1+AG49) | AH12: =AD12*(1+AH49) | AI12: =AE12*(1+AI49) | AJ12: =AF12*(1+AJ49) | AK12: =AG12*(1+AK49) | AL12: =AH12*(1+AL49)
A13: Other Bets | C13: =Model_Base!C13 | D13: =Model_Base!D13 | E13: =Model_Base!E13 | F13: =Model_Base!F13 | G13: =Model_Base!G13 | H13: =Model_Base!H13 | I13: =Model_Base!I13 | J13: =Model_Base!J13 | ... AF13: =Model_Base!AF13 | AG13: =AC13*(1+AG50) | AH13: =AD13*(1+AH50) | AI13: =AE13*(1+AI50) | AJ13: =AF13*(1+AJ50) | AK13: =AG13*(1+AK50) | AL13: =AH13*(1+AL50)
A14: Hedging gains / (losses) | C14: =Model_Base!C14 | D14: =Model_Base!D14 | E14: =Model_Base!E14 | F14: =Model_Base!F14 | G14: =Model_Base!G14 | H14: =Model_Base!H14 | I14: =Model_Base!I14 | J14: =Model_Base!J14 | ... AF14: =Model_Base!AF14 | AG14: 0 | AH14: 0 | AI14: 0 | AJ14: 0 | AK14: 0 | AL14: 0
A15: Total revenues | C15: =SUM(C8:C14) | D15: =SUM(D8:D14) | E15: =SUM(E8:E14) | F15: =SUM(F8:F14) | G15: =SUM(G8:G14) | H15: =SUM(H8:H14) | I15: =SUM(I8:I14) | J15: =SUM(J8:J14) | ... AL15: =SUM(AL8:AL14)
A17: YoY GROWTH
A18: Search & other | G18: =G8/C8-1 | H18: =H8/D8-1 | I18: =I8/E8-1 | J18: =J8/F8-1 | K18: =K8/G8-1 | L18: =L8/H8-1 | M18: =M8/I8-1 | N18: =N8/J8-1 | ... AL18: =AL8/AH8-1
A19: YouTube ads | G19: =G9/C9-1 | H19: =H9/D9-1 | I19: =I9/E9-1 | J19: =J9/F9-1 | K19: =K9/G9-1 | L19: =L9/H9-1 | M19: =M9/I9-1 | N19: =N9/J9-1 | ... AL19: =AL9/AH9-1
A20: Network | G20: =G10/C10-1 | H20: =H10/D10-1 | I20: =I10/E10-1 | J20: =J10/F10-1 | K20: =K10/G10-1 | L20: =L10/H10-1 | M20: =M10/I10-1 | N20: =N10/J10-1 | ... AL20: =AL10/AH10-1
A21: Subscriptions, platforms & devices | G21: =G11/C11-1 | H21: =H11/D11-1 | I21: =I11/E11-1 | J21: =J11/F11-1 | K21: =K11/G11-1 | L21: =L11/H11-1 | M21: =M11/I11-1 | N21: =N11/J11-1 | ... AL21: =AL11/AH11-1
A22: Google Cloud | G22: =G12/C12-1 | H22: =H12/D12-1 | I22: =I12/E12-1 | J22: =J12/F12-1 | K22: =K12/G12-1 | L22: =L12/H12-1 | M22: =M12/I12-1 | N22: =N12/J12-1 | ... AL22: =AL12/AH12-1
A23: Other Bets | G23: =G13/C13-1 | H23: =H13/D13-1 | I23: =I13/E13-1 | J23: =J13/F13-1 | K23: =K13/G13-1 | L23: =L13/H13-1 | M23: =M13/I13-1 | N23: =N13/J13-1 | ... AL23: =AL13/AH13-1
A24: Total revenues | G24: =G15/C15-1 | H24: =H15/D15-1 | I24: =I15/E15-1 | J24: =J15/F15-1 | K24: =K15/G15-1 | L24: =L15/H15-1 | M24: =M15/I15-1 | N24: =N15/J15-1 | ... AL24: =AL15/AH15-1
A26: PROFIT & LOSS
A27: Cost of revenues | C27: =Model_Base!C27 | D27: =Model_Base!D27 | E27: =Model_Base!E27 | F27: =Model_Base!F27 | G27: =Model_Base!G27 | H27: =Model_Base!H27 | I27: =Model_Base!I27 | J27: =Model_Base!J27 | ... AF27: =Model_Base!AF27 | AG27: =AG15*AG39 | AH27: =AH15*AH39 | AI27: =AI15*AI39 | AJ27: =AJ15*AJ39 | AK27: =AK15*AK39 | AL27: =AL15*AL39
A28: Gross profit | C28: =C15-C27 | D28: =D15-D27 | E28: =E15-E27 | F28: =F15-F27 | G28: =G15-G27 | H28: =H15-H27 | I28: =I15-I27 | J28: =J15-J27 | ... AL28: =AL15-AL27
A29: Gross margin | C29: =C28/C15 | D29: =D28/D15 | E29: =E28/E15 | F29: =F28/F15 | G29: =G28/G15 | H29: =H28/H15 | I29: =I28/I15 | J29: =J28/J15 | ... AL29: =AL28/AL15
A30: Research & development | C30: =Model_Base!C30 | D30: =Model_Base!D30 | E30: =Model_Base!E30 | F30: =Model_Base!F30 | G30: =Model_Base!G30 | H30: =Model_Base!H30 | I30: =Model_Base!I30 | J30: =Model_Base!J30 | ... AL30: =Model_Base!AL30
A31: Sales & marketing | C31: =Model_Base!C31 | D31: =Model_Base!D31 | E31: =Model_Base!E31 | F31: =Model_Base!F31 | G31: =Model_Base!G31 | H31: =Model_Base!H31 | I31: =Model_Base!I31 | J31: =Model_Base!J31 | ... AF31: =Model_Base!AF31 | AG31: =AG15*AG41 | AH31: =AH15*AH41 | AI31: =AI15*AI41 | AJ31: =AJ15*AJ41 | AK31: =AK15*AK41 | AL31: =AL15*AL41
A32: General & administrative | C32: =Model_Base!C32 | D32: =Model_Base!D32 | E32: =Model_Base!E32 | F32: =Model_Base!F32 | G32: =Model_Base!G32 | H32: =Model_Base!H32 | I32: =Model_Base!I32 | J32: =Model_Base!J32 | ... AL32: =Model_Base!AL32
A33: European Commission fines | C33: =Model_Base!C33 | D33: =Model_Base!D33 | E33: =Model_Base!E33 | F33: =Model_Base!F33 | G33: =Model_Base!G33 | H33: =Model_Base!H33 | I33: =Model_Base!I33 | J33: =Model_Base!J33 | ... AF33: =Model_Base!AF33 | AG33: 0 | AH33: 0 | AI33: 0 | AJ33: 0 | AK33: 0 | AL33: 0
A34: Total operating expenses (R&D + S&M + G&A + fines) | C34: =C30+C31+C32+C33 | D34: =D30+D31+D32+D33 | E34: =E30+E31+E32+E33 | F34: =F30+F31+F32+F33 | G34: =G30+G31+G32+G33 | H34: =H30+H31+H32+H33 | I34: =I30+I31+I32+I33 | J34: =J30+J31+J32+J33 | ... AL34: =AL30+AL31+AL32+AL33
A35: Operating income | C35: =C28-C34 | D35: =D28-D34 | E35: =E28-E34 | F35: =F28-F34 | G35: =G28-G34 | H35: =H28-H34 | I35: =I28-I34 | J35: =J28-J34 | ... AL35: =AL28-AL34
A36: Operating margin | C36: =C35/C15 | D36: =D35/D15 | E36: =E35/E15 | F36: =F35/F15 | G36: =G35/G15 | H36: =H35/H15 | I36: =I35/I15 | J36: =J35/J15 | ... AL36: =AL35/AL15
A38: COST RATIOS (% of revenue; forecast = trailing 4-quarter average)
A39: Cost of revenues | C39: =C27/C15 | D39: =D27/D15 | E39: =E27/E15 | F39: =F27/F15 | G39: =G27/G15 | H39: =H27/H15 | I39: =I27/I15 | J39: =J27/J15 | ... AF39: =AF27/AF15 | AG39: =AVERAGE(AC39:AF39) | AH39: =AVERAGE(AD39:AG39) | AI39: =AVERAGE(AE39:AH39) | AJ39: =AVERAGE(AF39:AI39) | AK39: =AVERAGE(AG39:AJ39) | AL39: =AVERAGE(AH39:AK39)
A40: R&D | C40: =C30/C15 | D40: =D30/D15 | E40: =E30/E15 | F40: =F30/F15 | G40: =G30/G15 | H40: =H30/H15 | I40: =I30/I15 | J40: =J30/J15 | ... AF40: =AF30/AF15 | AG40: =AVERAGE(AC40:AF40) | AH40: =AVERAGE(AD40:AG40) | AI40: =AVERAGE(AE40:AH40) | AJ40: =AVERAGE(AF40:AI40) | AK40: =AVERAGE(AG40:AJ40) | AL40: =AVERAGE(AH40:AK40)
A41: Sales & marketing | C41: =C31/C15 | D41: =D31/D15 | E41: =E31/E15 | F41: =F31/F15 | G41: =G31/G15 | H41: =H31/H15 | I41: =I31/I15 | J41: =J31/J15 | ... AF41: =AF31/AF15 | AG41: =AVERAGE(AC41:AF41) | AH41: =AVERAGE(AD41:AG41) | AI41: =AVERAGE(AE41:AH41) | AJ41: =AVERAGE(AF41:AI41) | AK41: =AVERAGE(AG41:AJ41) | AL41: =AVERAGE(AH41:AK41)
A42: G&A | C42: =C32/C15 | D42: =D32/D15 | E42: =E32/E15 | F42: =F32/F15 | G42: =G32/G15 | H42: =H32/H15 | I42: =I32/I15 | J42: =J32/J15 | ... AF42: =AF32/AF15 | AG42: =AVERAGE(AC42:AF42) | AH42: =AVERAGE(AD42:AG42) | AI42: =AVERAGE(AE42:AH42) | AJ42: =AVERAGE(AF42:AI42) | AK42: =AVERAGE(AG42:AJ42) | AL42: =AVERAGE(AH42:AK42)
A44: GROWTH ASSUMPTIONS = latest actual YoY x fade^k + scenario delta
...

Sheet Seasonality
A1: Seasonality: each quarter's share of full-year total revenue
A2: Q4 is consistently the largest quarter (holiday ad spend + Pixel launches), which is why every forecast quarter grows off the same quarter last year.
A4: Fiscal year | B4: Q1 | C4: Q2 | D4: Q3 | E4: Q4
A5: 2019 | B5: =Model_Base!C15/SUM(Model_Base!C15:F15) | C5: =Model_Base!D15/SUM(Model_Base!C15:F15) | D5: =Model_Base!E15/SUM(Model_Base!C15:F15) | E5: =Model_Base!F15/SUM(Model_Base!C15:F15)
A6: 2020 | B6: =Model_Base!G15/SUM(Model_Base!G15:J15) | C6: =Model_Base!H15/SUM(Model_Base!G15:J15) | D6: =Model_Base!I15/SUM(Model_Base!G15:J15) | E6: =Model_Base!J15/SUM(Model_Base!G15:J15)
A7: 2021 | B7: =Model_Base!K15/SUM(Model_Base!K15:N15) | C7: =Model_Base!L15/SUM(Model_Base!K15:N15) | D7: =Model_Base!M15/SUM(Model_Base!K15:N15) | E7: =Model_Base!N15/SUM(Model_Base!K15:N15)
A8: 2022 | B8: =Model_Base!O15/SUM(Model_Base!O15:R15) | C8: =Model_Base!P15/SUM(Model_Base!O15:R15) | D8: =Model_Base!Q15/SUM(Model_Base!O15:R15) | E8: =Model_Base!R15/SUM(Model_Base!O15:R15)
A9: 2023 | B9: =Model_Base!S15/SUM(Model_Base!S15:V15) | C9: =Model_Base!T15/SUM(Model_Base!S15:V15) | D9: =Model_Base!U15/SUM(Model_Base!S15:V15) | E9: =Model_Base!V15/SUM(Model_Base!S15:V15)
A10: 2024 | B10: =Model_Base!W15/SUM(Model_Base!W15:Z15) | C10: =Model_Base!X15/SUM(Model_Base!W15:Z15) | D10: =Model_Base!Y15/SUM(Model_Base!W15:Z15) | E10: =Model_Base!Z15/SUM(Model_Base!W15:Z15)
A11: 2025 | B11: =Model_Base!AA15/SUM(Model_Base!AA15:AD15) | C11: =Model_Base!AB15/SUM(Model_Base!AA15:AD15) | D11: =Model_Base!AC15/SUM(Model_Base!AA15:AD15) | E11: =Model_Base!AD15/SUM(Model_Base!AA15:AD15)
A12: Average | B12: =AVERAGE(B5:B11) | C12: =AVERAGE(C5:C11) | D12: =AVERAGE(D5:D11) | E12: =AVERAGE(E5:E11)
